<?xml version='1.0'?>

<robot name="my_robot" xmlns:xacro="http://www.ros.org/wiki/xacro">

  <xacro:include filename="$(find my_robot)/urdf/my_robot.gazebo" />
  <link name="robot_footprint"></link>

  <joint name="robot_footprint_joint" type="fixed">
    <origin xyz="0 0 0" rpy="0 0 0" />
    <parent link="robot_footprint"/>
    <child link="chassis" />
  </joint>

  <link name='chassis'>
    <pose>0 0 0.1 0 0 0</pose>

    <inertial>
      <mass value="15.0"/>
      <origin xyz="0.0 0 0" rpy=" 0 0 0"/>
      <inertia
          ixx="0.1" ixy="0" ixz="0"
          iyy="0.1" iyz="0"
          izz="0.1"
      />
    </inertial>

    <collision>
      <origin xyz="-0.15 0 0" rpy=" 0 0 0"/> 
      <geometry>
        <box size=".32 .4 .04"/>
      </geometry>
    </collision>

    <visual>
      <origin xyz="-0.15 0 0" rpy=" 0 0 0"/>
      <geometry>
        <box size=".32 .4 .04"/>
      </geometry>
    </visual>
    
    <collision>
      <origin xyz="0.15 0 0" rpy=" 0 0 0"/> 
      <geometry>
        <box size=".3 .2 .04"/>
      </geometry>
    </collision>

    <visual>
      <origin xyz="0.15 0 0" rpy=" 0 0 0"/>
      <geometry>
        <box size=".3 .2 .04"/>
      </geometry>
    </visual>

    <collision>
      <origin xyz=".2 0 0.07" rpy=" 0 0 0"/> 
      <geometry>
        <cylinder radius="0.05" length="0.1"/>
      </geometry>
    </collision>

    <visual>
      <origin xyz="0.2 0 0.07" rpy=" 0 0 0"/>
      <geometry>
        <cylinder radius="0.05" length="0.1"/>
      </geometry>
    </visual>
  </link>

  <link name='motor'>
    <collision>
      <origin xyz="0 0 0" rpy=" 0 1.5707 1.5707"/> 
      <geometry>
        <cylinder radius="0.05" length="0.45"/>
      </geometry>
    </collision>

    <visual>
      <origin xyz="0 0 0" rpy=" 0 1.5707 1.5707"/>
      <geometry>
        <cylinder radius="0.05" length="0.45"/>
      </geometry>
    </visual>
  </link>

  <link name='plow'>
    <inertial>
        <origin xyx="0 0 0" rpy="0 0 0"/>
        <mass value="1"/>
        <inertia
        ixx="0.1" ixy="0" ixz="0"
        iyy="0.1" iyz="0"
        izz="0.2"
        />
     </inertial>
    <collision>
      <origin xyz="0 0 -0.1" rpy=" 0 0 0"/> 
      <geometry>
        <box size="0.01 0.6 0.2"/>
      </geometry>
    </collision>

    <visual>
      <origin xyz="0 0 -0.1" rpy=" 0 0 0"/> 
      <geometry>
        <box size="0.01 0.6 0.2"/>
      </geometry>
    </visual>
    
    <collision>
      <origin xyz="0.00707 0.30707 -0.1" rpy=" 0 0 -0.7854"/> 
      <geometry>
        <box size="0.01 0.02 0.2"/>
      </geometry>
    </collision>

    <visual>
      <origin xyz="0.00707 0.30707 -0.1" rpy=" 0 0 -0.7854"/> 
      <geometry>
        <box size="0.01 0.02 0.2"/>
      </geometry>
    </visual>

    <collision>
      <origin xyz="0.00707 -0.30707 -0.1" rpy=" 0 0 0.7854"/> 
      <geometry>
        <box size="0.01 0.02 0.2"/>
      </geometry>
    </collision>

    <visual>
      <origin xyz="0.00707 -0.30707 -0.1" rpy=" 0 0 0.7854"/> 
      <geometry>
        <box size="0.01 0.02 0.2"/>
      </geometry>
    </visual>
  </link>

  <link name='fork'>
     <inertial>
        <origin xyx="0 0 0" rpy="0 0 0"/>
        <mass value="2"/>
        <inertia
        ixx="0.1" ixy="0" ixz="0"
        iyy="0.1" iyz="0"
        izz="0.2"
        />
     </inertial>
     
     <collision name="fork_collision">
       <origin xyx="0 0 0" rpy="0 0 0"/>
       <geometry>
         <box size="0.12 0.02 0.1"/>
       </geometry>
     </collision>
     <visual name="fork_visual">
       <origin xyx="0 0 0" rpy="0 0 0"/>
       <geometry>
         <box size="0.12 0.02 0.1"/>
       </geometry>
     </visual>
  </link>

  <link name='front_wheel'>
    <inertial>
      <origin xyz="0 0 0" rpy="0 1.5707 1.5707"/>
      <mass value="5"/>
      <inertia
      ixx="0.1" ixy="0" ixz="0"
      iyy="0.1" iyz="0"
      izz="0.1"
      />
    </inertial>
 
    <collision name='front_wheel_collision'>
      <origin xyz="0 0 0" rpy="0 1.5707 1.5707"/>
      <geometry>
        <cylinder radius="0.08" length="0.05"/>
      </geometry>
    </collision>

    <visual name='front_wheel_visual'>
      <origin xyz="0 0 0" rpy="0 0 1.5707"/>
      <geometry>
        <mesh filename="package://my_robot/meshes/wheel_model.dae" scale=".9 0.9 0.9"/>
      </geometry>
    </visual>
  </link>

   <link name='rear_left_wheel'>
    <inertial>
      <origin xyz="0 0 0" rpy="0 1.5707 1.5707"/>
      <mass value="5"/>
      <inertia
      ixx="0.1" ixy="0" ixz="0"
      iyy="0.1" iyz="0"
      izz="0.1"
      />
    </inertial>
 
    <collision name='rear_left_wheel_collision'>
      <origin xyz="0 0 0" rpy="0 1.5707 1.5707"/>
      <geometry>
        <cylinder radius="0.2" length="0.05"/>
      </geometry>
    </collision>

    <visual name='rear_left_wheel_visual'>
      <origin xyz="0 0 0" rpy="0 0 1.5707"/>
      <geometry>
        <mesh filename="package://my_robot/meshes/wheel_model.dae" scale="2 2 2"/>
      </geometry>
    </visual>
  </link>

  <link name='rear_right_wheel'>
    <inertial>
      <origin xyz="0 0 0" rpy="0 1.5707 1.5707"/>
      <mass value="5"/>
      <inertia
      ixx="0.1" ixy="0" ixz="0"
      iyy="0.1" iyz="0"
      izz="0.1"
      />
    </inertial>
 
    <collision name='rear_right_wheel_collision'>
      <origin xyz="0 0 0" rpy="0 1.5707 1.5707"/>
      <geometry>
        <cylinder radius="0.2" length="0.05"/>
      </geometry>
    </collision>

    <visual name='rear_right_wheel_visual'>
      <origin xyz="0 0 0" rpy="0 0 1.5707"/>
      <geometry>
        <mesh filename="package://my_robot/meshes/wheel_model.dae" scale="2 2 2"/>
      </geometry>
    </visual>
  </link>

  <link name="camera">
    <origin xyz="0 0 0" rpy="0 0 0"/>
    <inertial>
      <mass value="0.1"/>
      <inertia 
      ixx="1e-6" ixy="0" ixz="0"
      iyy="1e-6" iyz="0"
      izz="1e-6"
      />
    </inertial>

    <collision name="camera_collision">
      <origin xyx="0 0 0" rpy="0 0 0"/>
      <geometry>
        <box size="0.05 0.05 0.05"/>
      </geometry>    
    </collision>

    <visual name="camera_visual">
      <origin xyx="0 0 0" rpy="0 0 0"/>
      <geometry>
        <box size="0.05 0.05 0.05"/>
      </geometry>    
    </visual>

  </link>

  <link name="hokuyo">
    <origin xyz="0 0 0" rpy="0 0 0"/>
    <inertial>
      <mass value="1e-5"/>
      <inertia 
      ixx="1e-6" ixy="0" ixz="0"
      iyy="1e-6" iyz="0"
      izz="1e-6"
      />
    </inertial>

    <collision name="hokuyo_collision">
      <origin xyx="0 0 0" rpy="0 0 0"/>
      <geometry>
        <box size="0.1 0.1 0.1"/>
      </geometry>    
    </collision>

    <visual name="hokuyo_visual">
      <origin xyx="0 0 0" rpy="0 0 0"/>
      <geometry>
        <mesh filename="package://my_robot/meshes/hokuyo.dae"/>      
      </geometry>    
    </visual>
  </link>

   <joint type="continuous" name="fork_top_hinge">
    <origin xyz="0.2 0.0 -0.08" rpy="0 0 0"/>
    <child link="fork"/>
    <parent link="chassis"/>
    <axis xyz="0 0 1" rpy="0 0 0"/>
  </joint>
  
  <joint type="continuous" name="front_wheel_hinge">
    <origin xyz="-0.05 0.04 -0.05" rpy="0 0 0"/>
    <child link="front_wheel"/>
    <parent link="fork"/>
    <axis xyz="0 1 0" rpy="0 0 0"/>
  </joint>

  <joint type="continuous" name="rear_left_wheel_hinge">
    <origin xyz="-0.25 0.3 0" rpy="0 0 0"/>
    <child link="rear_left_wheel"/>
    <parent link="chassis"/>
    <axis xyz="0 1 0" rpy="0 0 0"/>
    <limit effort="10000" velocity="1000"/>
    <dynamics damping="1.0" friction="0.0"/>
  </joint>

  <joint type="continuous" name="rear_right_wheel_hinge">
    <origin xyz="-0.25 -0.3 0" rpy="0 0 0"/>
    <child link="rear_right_wheel"/>
    <parent link="chassis"/>
    <axis xyz="0 1 0" rpy="0 0 0"/>
    <limit effort="10000" velocity="1000"/>
    <dynamics damping="1.0" friction="0.0"/>
  </joint>

  <joint type="fixed" name="camera_joint">
    <origin xyz="0.3 0 0" rpy="0 0 0"/>
    <child link="camera"/>
    <parent link="chassis"/>
    <axis xyz="0 1 0" rpy="0 0 0"/>
  </joint>

  <joint type="fixed" name="hokuyo_joint">
    <origin xyz="0.2 0 0.12" rpy="0 0 0"/>
    <child link="hokuyo"/>
    <parent link="chassis"/>
    <axis xyz="0 1 0" rpy="0 0 0"/>
  </joint>

  <joint type="fixed" name="plow_joint">
    <origin xyz="0.3 0 0"/>
    <child link="plow"/>
    <parent link="chassis"/>
    <axis xyz="1 0 0" rpy="0 0 0"/>
  </joint>

  <joint type="fixed" name="motor_joint">
    <origin xyz="-0.25 0 0"/>
    <child link="motor"/>
    <parent link="chassis"/>
    <axis xyz="1 0 0" rpy="0 0 0"/>
  </joint>


</robot>

